Workbook

Sheet Инструкция
B2: Модель TCO (Total Cost of Ownership) - кейс «Africa Delivery», горизонт 5 лет
B4: Зачем этот файл
B5: Задача | C5: Оценить полную стоимость владения выбранным архитектурным вариантом на 5 лет и использовать цифры как аргумент в ADR №1 («Выбор архитектурного стиля»).
B6: Как использовать | C6: Заполни один и тот же шаблон для каждого рассматриваемого варианта (например: модульный монолит / SOA / микросервисы) - сравнивать нужно итоги, а не ощущения.
B8: Цветовая легенда
B9: Синий текст на жёлтом фоне | C9: Ячейки для заполнения. Только их и редактируем.
B10: Чёрный текст | C10: Формулы. Не трогаем - пересчитаются сами.
B11: Зелёный текст | C11: Ссылка на лист «Допущения».
B13: Порядок работы
B14: Шаг 1 | C14: Лист «Допущения» -> блок 1: вбить драйверы бизнеса по годам (активные пользователи, число заказов, средний чек). Из них считается GMV.
B15: Шаг 2 | C15: Лист «Допущения» -> блок 2: финансовые допущения (инфляция, рост ФОТ, ставка дисконтирования, резерв, целевой SLO).
B16: Шаг 3 | C16: Лист «TCO» -> в колонке «База, $/год (Год 1)» указать затраты первого года по каждой статье. Лишние статьи оставить пустыми, свои - дописать в свободные строки.
B17: Шаг 4 | C17: Лист «TCO» -> в колонке «Драйвер роста» выбрать из выпадающего списка, от чего растёт статья: фикс / инфляция / ФОТ / пользователи / заказы / GMV. Годы 2–5 посчитаются сами.
B18: Шаг 5 | C18: Посмотреть блок «Ключевые метрики» внизу листа «TCO»: итог за 5 лет, NPV, стоимость на заказ, проверку бюджета CFO ($9k/мес на облако).
B20: Что важно не забыть в этом кейсе
B21: Бюджет CFO | C21: $5 000/мес на облако и SaaS (A6 п.1). $9 000 - цифра из board deck, разработке недоступна. Проверка в модели считает блоки 1+2.
B22: Цена простоя | C22: Инвестор оценивает минуту простоя в $12 000. Целевой SLO 99,99% = 52,6 мин/год ≈ $631k. Этот риск считается отдельным блоком - сравни его со стоимостью резервирования.
B23: Транзакционные расходы | C23: Комиссии M-Pesa / Flutterwave / Paystack, SMS и WhatsApp растут с GMV и числом заказов и на горизонте 5 лет обычно обгоняют инфраструктуру. Не забудь их - это типичная ошибка.
B24: Сравнение вариантов | C24: Транзакционные расходы (блок 3) почти одинаковы для любой архитектуры - это pass-through от оборота. Варианты архитектуры сравнивай по блокам 1, 2, 4 и 6.
B25: Разовые затраты | C25: Комплаенс-аудит NDPR/POPIA, пентест, миграция - если статья возникает не каждый год, просто перезапиши формулу в нужной ячейке года числом (и покрась в синий).
B26: Люди | C26: ФОТ команды - обычно самая крупная статья TCO. Микросервисы дешевле в масштабировании, но дороже в эксплуатации: это должно быть видно в цифрах, а не только в тексте ADR.
B30: Как устроен этот файл (Africa Delivery, задание 2)
B31: Листы | C31: На каждый вариант - копия шаблона: «Допущения A/B/C» + «TCO A/B/C». Драйверы бизнеса заданы один раз в «Допущения A», остальные ссылаются на них. Итоги - на листах «Сравнение» и «Цена ошибки».
B32: Отличия от шаблона | C32: Бюджет CFO = $5 000 (A6 п.1, а не $9k). Проверка бюджета считает блоки 1+2 (облако + SaaS). Добавлен драйвер «масштаб» = пользователи^0,7. ФОТ задан по FTE на каждый год. Разовые статьи в годах 2–5 обнулены вручную. Блок 6 считает минуту простоя от GMV (плоские $12k - в чувствительности).

Sheet Сравнение
B2: Сравнение вариантов - ключевые метрики (считаются из листов TCO A/B/C)
B4: Метрика | C4: A: Модульный монолит | D4: B: Сервисная (6) | E4: C: Микросервисы CTO | F4: Комментарий
B5: Облако + SaaS, $/мес, Год 1 | C5: ='TCO A'!E63 -> 4750 | D5: ='TCO B'!E63 -> 8650 | E5: ='TCO C'!E63 -> 23658.333 | F5: Лимит CFO $5 000 (A6 п.1)
B6: Проверка бюджета CFO | C6: ='TCO A'!E64 -> В бюджете CFO | D6: ='TCO B'!E64 -> ПРЕВЫШЕНИЕ бюджета | E6: ='TCO C'!E64 -> ПРЕВЫШЕНИЕ бюджета
B7: Блок 1+2 за 5 лет, $ | C7: ='TCO A'!J15+'TCO A'!J24 -> 1010431.8 | D7: ='TCO B'!J15+'TCO B'!J24 -> 1650122.3 | E7: ='TCO C'!J15+'TCO C'!J24 -> 4023033.2
B8: Команда (ФОТ) за 5 лет, $ | C8: ='TCO A'!J40 -> 8625331 | D8: ='TCO B'!J40 -> 10104625 | E8: ='TCO C'!J40 -> 14650555 | F8: Крупнейшая архитектурно-зависимая статья
B9: Разовые и комплаенс за 5 лет, $ | C9: ='TCO A'!J48 -> 236527.49 | D9: ='TCO B'!J48 -> 336820.2 | E9: ='TCO C'!J48 -> 574169.86
B10: Транзакционные за 5 лет, $ | C10: ='TCO A'!J32 -> 27332200 | D10: ='TCO B'!J32 -> 27332200 | E10: ='TCO C'!J32 -> 27332200 | F10: Одинаковы для всех вариантов (pass-through)
B11: TCO 5 лет, прямые затраты, $ | C11: ='TCO A'!J51 -> 42785164 | D11: ='TCO B'!J51 -> 45337333 | E11: ='TCO C'!J51 -> 53566952
B12: Архитектурно-зависимые затраты 5 лет, $ | C12: ='TCO A'!E75 -> 11353134 | D12: ='TCO B'!E75 -> 13905303 | E12: ='TCO C'!E75 -> 22134922 | F12: Блоки 1,2,4,5 + резерв
B13: Стоимость простоя 5 лет (от GMV), $ | C13: ='TCO A'!J53 -> 4397000 | D13: ='TCO B'!J53 -> 2198500 | E13: ='TCO C'!J53 -> 439700 | F13: MIN($12k; GMV/мин × 5)
B14: TCO 5 лет с простоем (от GMV), $ | C14: ='TCO A'!J54 -> 47182164 | D14: ='TCO B'!J54 -> 47535833 | E14: ='TCO C'!J54 -> 54006652
B15: NPV затрат 5 лет, $ | C15: ='TCO A'!J56 -> 27630566 | D15: ='TCO B'!J56 -> 28107426 | E15: ='TCO C'!J56 -> 32564740 | F15: Ставка 20%
B16: Стоимость заказа, Год 1, $ | C16: ='TCO A'!E71 -> 2.2754667 | D16: ='TCO B'!E71 -> 2.852 | E16: ='TCO C'!E71 -> 4.489025 | F16: A6: на объёмах запуска
B17: Стоимость заказа, Год 2, $ | C17: ='TCO A'!E72 -> 1.3636565 | D17: ='TCO B'!E72 -> 1.549967 | E17: ='TCO C'!E72 -> 2.0731395 | F17: A6: через 12 месяцев
B18: ИТ без транзакционных на заказ, Год 1, $ | C18: ='TCO A'!E73 -> 1.5314167 | D18: ='TCO B'!E73 -> 2.10795 | E18: ='TCO C'!E73 -> 3.744975
B19: ИТ без транзакционных на заказ, Год 2, $ | C19: ='TCO A'!E74 -> 0.59315652 | D19: ='TCO B'!E74 -> 0.77946701 | E19: ='TCO C'!E74 -> 1.3026395
B20: TCO на заказ за 5 лет, $ | C20: ='TCO A'!E65 -> 1.1259254 | D20: ='TCO B'!E65 -> 1.1930877 | E20: ='TCO C'!E65 -> 1.4096566
B21: ИТ-затраты как доля GMV (5 лет) | C21: ='TCO A'!E67 -> 0.048652677 | D21: ='TCO B'!E67 -> 0.051554848 | E21: ='TCO C'!E67 -> 0.060913068
B22: SLO | C22: ='Допущения A'!C20 -> 0.999 | D22: ='Допущения B'!C20 -> 0.9995 | E22: ='Допущения C'!C20 -> 0.9999
B23: Простой при плоских $12k/мин, 5 лет, $ | C23: =(1-'Допущения A'!C20)*525600*12000*5 -> 31536000 | D23: =(1-'Допущения B'!C20)*525600*12000*5 -> 15768000 | E23: =(1-'Допущения C'!C20)*525600*12000*5 -> 3153600 | F23: Чувствительность: если верить $12k/мин всегда
B24: TCO 5 лет с простоем при $12k/мин, $ | C24: ='TCO A'!J51+(1-'Допущения A'!C20)*525600*12000*5 -> 74321164 | D24: ='TCO B'!J51+(1-'Допущения B'!C20)*525600*12000*5 -> 61105333 | E24: ='TCO C'!J51+(1-'Допущения C'!C20)*525600*12000*5 -> 56720552
B26: Точка безубыточности высокой доступности
B27: Доп. затраты C над A в Год 2, $/год | C27: ='TCO C'!F51-'TCO A'!F51 -> 1702759.2
B28: Минут простоя, которые экономит 99,99% против 99,9%, в год | C28: =('Допущения C'!C20-'Допущения A'!C20)*525600 -> 473.04
B29: Безубыточная стоимость минуты простоя, $ | C29: =C27/C28 -> 3599.6093
B30: GMV в год, при котором средняя минута (×5 пик) стоит столько, $ | C30: =C29*525600/'Допущения A'!C22 -> 3.7839093e+08
B31: Вывод: пока GMV ниже этого уровня, переплата за 99,99% в стиле C больше предотвращённых потерь. Это триггер пересмотра, а не довод в пользу стиля C.

Sheet Цена ошибки
B2: Цена ошибки (запрос CFO, A6): построили под 10 млн - пришло 50 тыс., и обратный случай
B4: Сценарий 1. Построили под 10M (вариант C), пришло 50 000 пользователей
B5: Горизонт оценки, мес (runway, A6 п.3) | C5: 9
B6: Облако+SaaS C, Год 1, $/мес (почти не зависит от трафика: ёмкость выделена под 10M) | C6: ='TCO C'!E63 -> 23658.333
B7: Облако+SaaS A при 50k пользователей, $/мес (минимальный размер ~ Год 1) | C7: ='TCO A'!E63 -> 4750
B8: Лишняя инфраструктура за горизонт, $ | C8: =(C6-C7)*C5 -> 170175
B9: Лишняя команда за горизонт (ФОТ C − ФОТ A, Год 1), $ | C9: =('TCO C'!E40-'TCO A'!E40)*C5/12 -> 643500
B10: Лишние разовые (найм, интеграции; лицензия Oracle уже в строке 6), $ | C10: ='TCO C'!E48-'TCO A'!E48 -> 70000
B11: ИТОГО потрачено впустую за 9 месяцев, $ | C11: =C8+C9+C10 -> 883675
B12: Для сравнения: весь лимит облака CFO за 9 месяцев, $ | C12: =5000*C5 -> 45000
B14: Сценарий 2. Построили модульный монолит (A), пришло 10M - стоимость переделки
B15: Выделение горячих модулей в сервисы (каталог/поиск, заказ/оплата, уведомления), чел.-мес | C15: 18
B16: Ставка, $/чел.-мес | C16: 5500
B17: Переход на managed Kafka-совместимый брокер и шардирование БД, чел.-мес | C17: 8
B18: Временное усиление SRE на 6 мес, $ | C18: 39000
B19: ИТОГО стоимость переделки, $ | C19: =(C15+C17)*C16+C18 -> 182000
B20: Почему дёшево: границы модулей = будущие границы сервисов, outbox-события уже есть; переписывания нет, есть вынос.
B22: Асимметрия: ошибка «построили большое» стоит в несколько раз больше, чем «построили малое и выросли», и наступает сразу, а не при успехе.

Sheet Допущения A
B2: Допущения модели TCO - вариант A: Модульный монолит
B3: Заполняются только ячейки с жёлтой заливкой. Все числа ниже - пример, заменить своими.
B5: 1. Драйверы бизнеса - заполнить
B6: Показатель | C6: Год 1 | D6: Год 2 | E6: Год 3 | F6: Год 4 | G6: Год 5 | H6: Комментарий / источник
B7: Активные пользователи (на конец года) | C7: 400000 | D7: 1200000 | E7: 2500000 | F7: 4000000 | G7: 6000000 | H7: База: >1 млн зарегистрированных за 12 мес (кейс), 400k активных на конец Г1; рост до 15 стран (A1)
B8: Число заказов в год | C8: 600000 | D8: 2400000 | E8: 6000000 | F8: 11000000 | G8: 18000000 | H8: 1,5 заказа на активного в Г1, растёт с частотой покупок
B9: Средний чек (AOV), $ | C9: 20 | D9: 21 | E9: 22 | F9: 23 | G9: 24 | H9: Низкая цена - ставка кейса; Android < $150 (A2)
B10: GMV, $ в год (расчёт) | C10: =C8*C9 -> 12000000 | D10: =D8*D9 -> 50400000 | E10: =E8*E9 -> 132000000 | F10: =F8*F9 -> 253000000 | G10: =G8*G9 -> 432000000 | H10: Расчёт: заказы × средний чек
B12: 2. Финансовые допущения - заполнить
B13: Параметр | C13: Значение | H13: Комментарий / источник
B14: Инфляция затрат, % в год | C14: 0.08 | H14: Применяется к статьям с драйвером «инфляция»
B15: Рост ФОТ, % в год | C15: 0.12 | H15: Дефицит ИТ-специалистов на рынке - рост выше инфляции
B16: Ставка дисконтирования, % в год | C16: 0.2 | H16: Для расчёта NPV затрат. Стартап, высокий риск
B17: Резерв на непредвиденное (contingency), % | C17: 0.15 | H17: Надбавка к прямым затратам
B18: Бюджет CFO на облако, $/мес | C18: 5000 | H18: A6 п.1: $5 000/мес - жёсткий потолок, включая мониторинг и SaaS. $9 000 - цифра из board deck, разработке недоступна
B19: Стоимость минуты простоя, $ | C19: 12000 | H19: Оценка инвестора «в распродажу» (A1, A7). В блоке 6 минута считается от GMV, плоские $12k - на листе «Сравнение»
B20: Целевой SLO (доступность), % | C20: 0.999 | H20: Мультизонно в одной стране; управляемая деградация
B21: Учитывать стоимость простоя в TCO (1 - да, 0 - нет) | C21: 1 | H21: Переключатель для сценарного анализа
B22: Коэффициент пиковости простоя (× к средней GMV/мин) | C22: 5 | H22: Сбои концентрируются в часы пик и распродаж
B23: 3. Индексы роста - расчёт, не редактировать
B24: Драйвер | C24: Год 1 | D24: Год 2 | E24: Год 3 | F24: Год 4 | G24: Год 5 | H24: Как считается
B25: фикс | C25: 1 | D25: 1 | E25: 1 | F25: 1 | G25: 1 | H25: Затраты не меняются по годам
B26: инфляция | C26: 1 | D26: =C26*(1+$C$14) -> 1.08 | E26: =D26*(1+$C$14) -> 1.1664 | F26: =E26*(1+$C$14) -> 1.259712 | G26: =F26*(1+$C$14) -> 1.360489 | H26: Год N = Год N-1 × (1 + инфляция)
B27: ФОТ | C27: 1 | D27: =C27*(1+$C$15) -> 1.12 | E27: =D27*(1+$C$15) -> 1.2544 | F27: =E27*(1+$C$15) -> 1.404928 | G27: =F27*(1+$C$15) -> 1.5735194 | H27: Год N = Год N-1 × (1 + рост ФОТ)
B28: пользователи | C28: =C7/$C$7 -> 1 | D28: =D7/$C$7 -> 3 | E28: =E7/$C$7 -> 6.25 | F28: =F7/$C$7 -> 10 | G28: =G7/$C$7 -> 15 | H28: Пропорционально числу активных пользователей
B29: заказы | C29: =C8/$C$8 -> 1 | D29: =D8/$C$8 -> 4 | E29: =E8/$C$8 -> 10 | F29: =F8/$C$8 -> 18.333333 | G29: =G8/$C$8 -> 30 | H29: Пропорционально числу заказов
B30: GMV | C30: =C10/$C$10 -> 1 | D30: =D10/$C$10 -> 4.2 | E30: =E10/$C$10 -> 11 | F30: =F10/$C$10 -> 21.083333 | G30: =G10/$C$10 -> 36 | H30: Пропорционально обороту
B31: масштаб | C31: =(C7/$C$7)^0.7 -> 1 | D31: =(D7/$C$7)^0.7 -> 2.1576693 | E31: =(E7/$C$7)^0.7 -> 3.6067498 | F31: =(F7/$C$7)^0.7 -> 5.0118723 | G31: =(G7/$C$7)^0.7 -> 6.6567751 | H31: Сублинейный рост инфраструктуры: (пользователи)^0,7 - эффект масштаба (см. примечание B32)
B32: Драйвер «пользователи» - упрощение: облачные расходы редко растут строго линейно (есть эффект масштаба и обратный эффект - рост нагрузки на БД). При желании введи свой драйвер отдельной строкой в таблице индексов.
B33: Драйвер «масштаб» добавлен по рекомендации B32; все варианты используют одинаковые драйверы.

Sheet TCO A
B2: TCO на 5 лет - вариант A: Модульный монолит
B3: Заполняем колонки «Драйвер роста» и «База, $/год (Год 1)». Годы 1–5 считаются автоматически.
B5: Статья затрат | C5: Драйвер роста | D5: База, $/год (Год 1) | E5: Год 1 | F5: Год 2 | G5: Год 3 | H5: Год 4 | I5: Год 5 | J5: Итого 5 лет | K5: Доля | L5: Комментарий / источник
B6: БЛОК 1. Облачная инфраструктура (OpEx)
B7: Compute: ноды / контейнеры / serverless | C7: масштаб | D7: 14400 | E7: =IF($D7="","",$D7*INDEX('Допущения A'!$C$25:$G$31,MATCH($C7,'Допущения A'!$B$25:$B$31,0),1)) -> 14400 | F7: =IF($D7="","",$D7*INDEX('Допущения A'!$C$25:$G$31,MATCH($C7,'Допущения A'!$B$25:$B$31,0),2)) -> 31070.438 | G7: =IF($D7="","",$D7*INDEX('Допущения A'!$C$25:$G$31,MATCH($C7,'Допущения A'!$B$25:$B$31,0),3)) -> 51937.197 | H7: =IF($D7="","",$D7*INDEX('Допущения A'!$C$25:$G$31,MATCH($C7,'Допущения A'!$B$25:$B$31,0),4)) -> 72170.962 | I7: =IF($D7="","",$D7*INDEX('Допущения A'!$C$25:$G$31,MATCH($C7,'Допущения A'!$B$25:$B$31,0),5)) -> 95857.561 | J7: =SUM(E7:I7) -> 265436.16 | L7: Один кластер Kubernetes на страну (NG, KE): 3 ноды по 4 vCPU, автоскейлинг. ~$1 200/мес
B8: Управляемые БД (PostgreSQL, реплики) | C8: масштаб | D8: 9600 | E8: =IF($D8="","",$D8*INDEX('Допущения A'!$C$25:$G$31,MATCH($C8,'Допущения A'!$B$25:$B$31,0),1)) -> 9600 | F8: =IF($D8="","",$D8*INDEX('Допущения A'!$C$25:$G$31,MATCH($C8,'Допущения A'!$B$25:$B$31,0),2)) -> 20713.625 | G8: =IF($D8="","",$D8*INDEX('Допущения A'!$C$25:$G$31,MATCH($C8,'Допущения A'!$B$25:$B$31,0),3)) -> 34624.798 | H8: =IF($D8="","",$D8*INDEX('Допущения A'!$C$25:$G$31,MATCH($C8,'Допущения A'!$B$25:$B$31,0),4)) -> 48113.974 | I8: =IF($D8="","",$D8*INDEX('Допущения A'!$C$25:$G$31,MATCH($C8,'Допущения A'!$B$25:$B$31,0),5)) -> 63905.04 | J8: =SUM(E8:I8) -> 176957.44 | L8: Managed PostgreSQL: primary + синхронная реплика в другой AZ, по стране. ~$800/мес
B9: Хранилище объектов и резервные копии | C9: пользователи | D9: 2400 | E9: =IF($D9="","",$D9*INDEX('Допущения A'!$C$25:$G$31,MATCH($C9,'Допущения A'!$B$25:$B$31,0),1)) -> 2400 | F9: =IF($D9="","",$D9*INDEX('Допущения A'!$C$25:$G$31,MATCH($C9,'Допущения A'!$B$25:$B$31,0),2)) -> 7200 | G9: =IF($D9="","",$D9*INDEX('Допущения A'!$C$25:$G$31,MATCH($C9,'Допущения A'!$B$25:$B$31,0),3)) -> 15000 | H9: =IF($D9="","",$D9*INDEX('Допущения A'!$C$25:$G$31,MATCH($C9,'Допущения A'!$B$25:$B$31,0),4)) -> 24000 | I9: =IF($D9="","",$D9*INDEX('Допущения A'!$C$25:$G$31,MATCH($C9,'Допущения A'!$B$25:$B$31,0),5)) -> 36000 | J9: =SUM(E9:I9) -> 84600 | L9: S3-совместимое хранилище: фото 5 000 SKU в WebP, бэкапы
B10: CDN и исходящий трафик | C10: пользователи | D10: 6000 | E10: =IF($D10="","",$D10*INDEX('Допущения A'!$C$25:$G$31,MATCH($C10,'Допущения A'!$B$25:$B$31,0),1)) -> 6000 | F10: =IF($D10="","",$D10*INDEX('Допущения A'!$C$25:$G$31,MATCH($C10,'Допущения A'!$B$25:$B$31,0),2)) -> 18000 | G10: =IF($D10="","",$D10*INDEX('Допущения A'!$C$25:$G$31,MATCH($C10,'Допущения A'!$B$25:$B$31,0),3)) -> 37500 | H10: =IF($D10="","",$D10*INDEX('Допущения A'!$C$25:$G$31,MATCH($C10,'Допущения A'!$B$25:$B$31,0),4)) -> 60000 | I10: =IF($D10="","",$D10*INDEX('Допущения A'!$C$25:$G$31,MATCH($C10,'Допущения A'!$B$25:$B$31,0),5)) -> 90000 | J10: =SUM(E10:I10) -> 211500 | L10: CDN, адаптивные изображения (A2: мегабайты считают)
B11: Очереди / стриминг (Kafka, SQS) | C11: заказы | D11: 600 | E11: =IF($D11="","",$D11*INDEX('Допущения A'!$C$25:$G$31,MATCH($C11,'Допущения A'!$B$25:$B$31,0),1)) -> 600 | F11: =IF($D11="","",$D11*INDEX('Допущения A'!$C$25:$G$31,MATCH($C11,'Допущения A'!$B$25:$B$31,0),2)) -> 2400 | G11: =IF($D11="","",$D11*INDEX('Допущения A'!$C$25:$G$31,MATCH($C11,'Допущения A'!$B$25:$B$31,0),3)) -> 6000 | H11: =IF($D11="","",$D11*INDEX('Допущения A'!$C$25:$G$31,MATCH($C11,'Допущения A'!$B$25:$B$31,0),4)) -> 11000 | I11: =IF($D11="","",$D11*INDEX('Допущения A'!$C$25:$G$31,MATCH($C11,'Допущения A'!$B$25:$B$31,0),5)) -> 18000 | J11: =SUM(E11:I11) -> 38000 | L11: Outbox в PostgreSQL + NATS JetStream в кластере; Kafka не нужна до триггера
B12: Резервный регион / DR | C12: инфляция | D12: 3600 | E12: =IF($D12="","",$D12*INDEX('Допущения A'!$C$25:$G$31,MATCH($C12,'Допущения A'!$B$25:$B$31,0),1)) -> 3600 | F12: =IF($D12="","",$D12*INDEX('Допущения A'!$C$25:$G$31,MATCH($C12,'Допущения A'!$B$25:$B$31,0),2)) -> 3888 | G12: =IF($D12="","",$D12*INDEX('Допущения A'!$C$25:$G$31,MATCH($C12,'Допущения A'!$B$25:$B$31,0),3)) -> 4199.04 | H12: =IF($D12="","",$D12*INDEX('Допущения A'!$C$25:$G$31,MATCH($C12,'Допущения A'!$B$25:$B$31,0),4)) -> 4534.9632 | I12: =IF($D12="","",$D12*INDEX('Допущения A'!$C$25:$G$31,MATCH($C12,'Допущения A'!$B$25:$B$31,0),5)) -> 4897.7603 | J12: =SUM(E12:I12) -> 21119.763 | L12: Холодный DR: бэкапы в соседний ЦОД страны + IaC, RTO ≤ 4 ч
B13: Локальное размещение данных (NDPR, Нигерия) | C13: инфляция | D13: 12000 | E13: =IF($D13="","",$D13*INDEX('Допущения A'!$C$25:$G$31,MATCH($C13,'Допущения A'!$B$25:$B$31,0),1)) -> 12000 | F13: =IF($D13="","",$D13*INDEX('Допущения A'!$C$25:$G$31,MATCH($C13,'Допущения A'!$B$25:$B$31,0),2)) -> 12960 | G13: =IF($D13="","",$D13*INDEX('Допущения A'!$C$25:$G$31,MATCH($C13,'Допущения A'!$B$25:$B$31,0),3)) -> 13996.8 | H13: =IF($D13="","",$D13*INDEX('Допущения A'!$C$25:$G$31,MATCH($C13,'Допущения A'!$B$25:$B$31,0),4)) -> 15116.544 | I13: =IF($D13="","",$D13*INDEX('Допущения A'!$C$25:$G$31,MATCH($C13,'Допущения A'!$B$25:$B$31,0),5)) -> 16325.868 | J13: =SUM(E13:I13) -> 70399.212 | L13: Надбавка локальных площадок Лагос/Найроби к цене hyperscaler (C-07)
C14: фикс | E14: =IF($D14="","",$D14*INDEX('Допущения A'!$C$25:$G$31,MATCH($C14,'Допущения A'!$B$25:$B$31,0),1)) | F14: =IF($D14="","",$D14*INDEX('Допущения A'!$C$25:$G$31,MATCH($C14,'Допущения A'!$B$25:$B$31,0),2)) | G14: =IF($D14="","",$D14*INDEX('Допущения A'!$C$25:$G$31,MATCH($C14,'Допущения A'!$B$25:$B$31,0),3)) | H14: =IF($D14="","",$D14*INDEX('Допущения A'!$C$25:$G$31,MATCH($C14,'Допущения A'!$B$25:$B$31,0),4)) | I14: =IF($D14="","",$D14*INDEX('Допущения A'!$C$25:$G$31,MATCH($C14,'Допущения A'!$B$25:$B$31,0),5)) | J14: =SUM(E14:I14) -> 0 | L14: Своя статья
B15: Итого по блоку | E15: =SUM(E7:E14) -> 48600 | F15: =SUM(F7:F14) -> 96232.063 | G15: =SUM(G7:G14) -> 163257.83 | H15: =SUM(H7:H14) -> 234936.44 | I15: =SUM(I7:I14) -> 324986.23 | J15: =SUM(J7:J14) -> 868012.57 | K15: =IFERROR(J15/$J$51,0) -> 0.0202877
B17: БЛОК 2. Лицензии, SaaS и инструменты
B18: Observability (метрики, логи, трейсинг) | C18: масштаб | D18: 1800 | E18: =IF($D18="","",$D18*INDEX('Допущения A'!$C$25:$G$31,MATCH($C18,'Допущения A'!$B$25:$B$31,0),1)) -> 1800 | F18: =IF($D18="","",$D18*INDEX('Допущения A'!$C$25:$G$31,MATCH($C18,'Допущения A'!$B$25:$B$31,0),2)) -> 3883.8047 | G18: =IF($D18="","",$D18*INDEX('Допущения A'!$C$25:$G$31,MATCH($C18,'Допущения A'!$B$25:$B$31,0),3)) -> 6492.1496 | H18: =IF($D18="","",$D18*INDEX('Допущения A'!$C$25:$G$31,MATCH($C18,'Допущения A'!$B$25:$B$31,0),4)) -> 9021.3702 | I18: =IF($D18="","",$D18*INDEX('Допущения A'!$C$25:$G$31,MATCH($C18,'Допущения A'!$B$25:$B$31,0),5)) -> 11982.195 | J18: =SUM(E18:I18) -> 33179.52 | L18: OSS: Prometheus + Loki + Grafana + Tempo в кластере (только хранилище)
B19: CI/CD, репозиторий, артефакты | C19: инфляция | D19: 1800 | E19: =IF($D19="","",$D19*INDEX('Допущения A'!$C$25:$G$31,MATCH($C19,'Допущения A'!$B$25:$B$31,0),1)) -> 1800 | F19: =IF($D19="","",$D19*INDEX('Допущения A'!$C$25:$G$31,MATCH($C19,'Допущения A'!$B$25:$B$31,0),2)) -> 1944 | G19: =IF($D19="","",$D19*INDEX('Допущения A'!$C$25:$G$31,MATCH($C19,'Допущения A'!$B$25:$B$31,0),3)) -> 2099.52 | H19: =IF($D19="","",$D19*INDEX('Допущения A'!$C$25:$G$31,MATCH($C19,'Допущения A'!$B$25:$B$31,0),4)) -> 2267.4816 | I19: =IF($D19="","",$D19*INDEX('Допущения A'!$C$25:$G$31,MATCH($C19,'Допущения A'!$B$25:$B$31,0),5)) -> 2448.8801 | J19: =SUM(E19:I19) -> 10559.882 | L19: GitHub Team + Actions, ArgoCD (OSS)
B20: Безопасность: WAF, секреты, антифрод | C20: пользователи | D20: 2400 | E20: =IF($D20="","",$D20*INDEX('Допущения A'!$C$25:$G$31,MATCH($C20,'Допущения A'!$B$25:$B$31,0),1)) -> 2400 | F20: =IF($D20="","",$D20*INDEX('Допущения A'!$C$25:$G$31,MATCH($C20,'Допущения A'!$B$25:$B$31,0),2)) -> 7200 | G20: =IF($D20="","",$D20*INDEX('Допущения A'!$C$25:$G$31,MATCH($C20,'Допущения A'!$B$25:$B$31,0),3)) -> 15000 | H20: =IF($D20="","",$D20*INDEX('Допущения A'!$C$25:$G$31,MATCH($C20,'Допущения A'!$B$25:$B$31,0),4)) -> 24000 | I20: =IF($D20="","",$D20*INDEX('Допущения A'!$C$25:$G$31,MATCH($C20,'Допущения A'!$B$25:$B$31,0),5)) -> 36000 | J20: =SUM(E20:I20) -> 84600 | L20: WAF/CDN-защита, секреты (OSS Vault/SOPS)
B21: WhatsApp Business API (подписка) | C21: инфляция | D21: 1200 | E21: =IF($D21="","",$D21*INDEX('Допущения A'!$C$25:$G$31,MATCH($C21,'Допущения A'!$B$25:$B$31,0),1)) -> 1200 | F21: =IF($D21="","",$D21*INDEX('Допущения A'!$C$25:$G$31,MATCH($C21,'Допущения A'!$B$25:$B$31,0),2)) -> 1296 | G21: =IF($D21="","",$D21*INDEX('Допущения A'!$C$25:$G$31,MATCH($C21,'Допущения A'!$B$25:$B$31,0),3)) -> 1399.68 | H21: =IF($D21="","",$D21*INDEX('Допущения A'!$C$25:$G$31,MATCH($C21,'Допущения A'!$B$25:$B$31,0),4)) -> 1511.6544 | I21: =IF($D21="","",$D21*INDEX('Допущения A'!$C$25:$G$31,MATCH($C21,'Допущения A'!$B$25:$B$31,0),5)) -> 1632.5868 | J21: =SUM(E21:I21) -> 7039.9212 | L21: Подписка BSP на WhatsApp Business API
B22: Прочее ПО и подписки | C22: инфляция | D22: 1200 | E22: =IF($D22="","",$D22*INDEX('Допущения A'!$C$25:$G$31,MATCH($C22,'Допущения A'!$B$25:$B$31,0),1)) -> 1200 | F22: =IF($D22="","",$D22*INDEX('Допущения A'!$C$25:$G$31,MATCH($C22,'Допущения A'!$B$25:$B$31,0),2)) -> 1296 | G22: =IF($D22="","",$D22*INDEX('Допущения A'!$C$25:$G$31,MATCH($C22,'Допущения A'!$B$25:$B$31,0),3)) -> 1399.68 | H22: =IF($D22="","",$D22*INDEX('Допущения A'!$C$25:$G$31,MATCH($C22,'Допущения A'!$B$25:$B$31,0),4)) -> 1511.6544 | I22: =IF($D22="","",$D22*INDEX('Допущения A'!$C$25:$G$31,MATCH($C22,'Допущения A'!$B$25:$B$31,0),5)) -> 1632.5868 | J22: =SUM(E22:I22) -> 7039.9212 | L22: Трекер, дизайн
C23: фикс | E23: =IF($D23="","",$D23*INDEX('Допущения A'!$C$25:$G$31,MATCH($C23,'Допущения A'!$B$25:$B$31,0),1)) | F23: =IF($D23="","",$D23*INDEX('Допущения A'!$C$25:$G$31,MATCH($C23,'Допущения A'!$B$25:$B$31,0),2)) | G23: =IF($D23="","",$D23*INDEX('Допущения A'!$C$25:$G$31,MATCH($C23,'Допущения A'!$B$25:$B$31,0),3)) | H23: =IF($D23="","",$D23*INDEX('Допущения A'!$C$25:$G$31,MATCH($C23,'Допущения A'!$B$25:$B$31,0),4)) | I23: =IF($D23="","",$D23*INDEX('Допущения A'!$C$25:$G$31,MATCH($C23,'Допущения A'!$B$25:$B$31,0),5)) | J23: =SUM(E23:I23) -> 0 | L23: Своя статья
B24: Итого по блоку | E24: =SUM(E18:E23) -> 8400 | F24: =SUM(F18:F23) -> 15619.805 | G24: =SUM(G18:G23) -> 26391.03 | H24: =SUM(H18:H23) -> 38312.161 | I24: =SUM(I18:I23) -> 53696.249 | J24: =SUM(J18:J23) -> 142419.24 | K24: =IFERROR(J24/$J$51,0) -> 0.0033287063
B26: БЛОК 3. Транзакционные расходы (Buy / Partner)
B27: Комиссии платёжных провайдеров | C27: GMV | D27: ='Допущения A'!C10*0.023 -> 276000 | E27: =IF($D27="","",$D27*INDEX('Допущения A'!$C$25:$G$31,MATCH($C27,'Допущения A'!$B$25:$B$31,0),1)) -> 276000 | F27: =IF($D27="","",$D27*INDEX('Допущения A'!$C$25:$G$31,MATCH($C27,'Допущения A'!$B$25:$B$31,0),2)) -> 1159200 | G27: =IF($D27="","",$D27*INDEX('Допущения A'!$C$25:$G$31,MATCH($C27,'Допущения A'!$B$25:$B$31,0),3)) -> 3036000 | H27: =IF($D27="","",$D27*INDEX('Допущения A'!$C$25:$G$31,MATCH($C27,'Допущения A'!$B$25:$B$31,0),4)) -> 5819000 | I27: =IF($D27="","",$D27*INDEX('Допущения A'!$C$25:$G$31,MATCH($C27,'Допущения A'!$B$25:$B$31,0),5)) -> 9936000 | J27: =SUM(E27:I27) -> 20226200 | L27: Комиссии PSP 2,3% GMV (лимит CFO 2,5%, A6 п.6): M-Pesa, Flutterwave, Paystack
B28: SMS-уведомления | C28: заказы | D28: 36000 | E28: =IF($D28="","",$D28*INDEX('Допущения A'!$C$25:$G$31,MATCH($C28,'Допущения A'!$B$25:$B$31,0),1)) -> 36000 | F28: =IF($D28="","",$D28*INDEX('Допущения A'!$C$25:$G$31,MATCH($C28,'Допущения A'!$B$25:$B$31,0),2)) -> 144000 | G28: =IF($D28="","",$D28*INDEX('Допущения A'!$C$25:$G$31,MATCH($C28,'Допущения A'!$B$25:$B$31,0),3)) -> 360000 | H28: =IF($D28="","",$D28*INDEX('Допущения A'!$C$25:$G$31,MATCH($C28,'Допущения A'!$B$25:$B$31,0),4)) -> 660000 | I28: =IF($D28="","",$D28*INDEX('Допущения A'!$C$25:$G$31,MATCH($C28,'Допущения A'!$B$25:$B$31,0),5)) -> 1080000 | J28: =SUM(E28:I28) -> 2280000 | L28: SMS: 3 транзакционных SMS на заказ × $0,02 (только opt-in, C-08)
B29: WhatsApp-сообщения (за диалог) | C29: заказы | D29: 9000 | E29: =IF($D29="","",$D29*INDEX('Допущения A'!$C$25:$G$31,MATCH($C29,'Допущения A'!$B$25:$B$31,0),1)) -> 9000 | F29: =IF($D29="","",$D29*INDEX('Допущения A'!$C$25:$G$31,MATCH($C29,'Допущения A'!$B$25:$B$31,0),2)) -> 36000 | G29: =IF($D29="","",$D29*INDEX('Допущения A'!$C$25:$G$31,MATCH($C29,'Допущения A'!$B$25:$B$31,0),3)) -> 90000 | H29: =IF($D29="","",$D29*INDEX('Допущения A'!$C$25:$G$31,MATCH($C29,'Допущения A'!$B$25:$B$31,0),4)) -> 165000 | I29: =IF($D29="","",$D29*INDEX('Допущения A'!$C$25:$G$31,MATCH($C29,'Допущения A'!$B$25:$B$31,0),5)) -> 270000 | J29: =SUM(E29:I29) -> 570000 | L29: WhatsApp: 0,5 utility-диалога на заказ × $0,03
B30: Логистика: интеграции и комиссии партнёров | C30: заказы | D30: 60000 | E30: =IF($D30="","",$D30*INDEX('Допущения A'!$C$25:$G$31,MATCH($C30,'Допущения A'!$B$25:$B$31,0),1)) -> 60000 | F30: =IF($D30="","",$D30*INDEX('Допущения A'!$C$25:$G$31,MATCH($C30,'Допущения A'!$B$25:$B$31,0),2)) -> 240000 | G30: =IF($D30="","",$D30*INDEX('Допущения A'!$C$25:$G$31,MATCH($C30,'Допущения A'!$B$25:$B$31,0),3)) -> 600000 | H30: =IF($D30="","",$D30*INDEX('Допущения A'!$C$25:$G$31,MATCH($C30,'Допущения A'!$B$25:$B$31,0),4)) -> 1100000 | I30: =IF($D30="","",$D30*INDEX('Допущения A'!$C$25:$G$31,MATCH($C30,'Допущения A'!$B$25:$B$31,0),5)) -> 1800000 | J30: =SUM(E30:I30) -> 3800000 | L30: Платформенный сбор Sendbox/Sendy $0,10 за отправление (доставку оплачивает покупатель)
B31: USSD-шлюз (сессии) | C31: заказы | D31: 7200 | E31: =IF($D31="","",$D31*INDEX('Допущения A'!$C$25:$G$31,MATCH($C31,'Допущения A'!$B$25:$B$31,0),1)) -> 7200 | F31: =IF($D31="","",$D31*INDEX('Допущения A'!$C$25:$G$31,MATCH($C31,'Допущения A'!$B$25:$B$31,0),2)) -> 28800 | G31: =IF($D31="","",$D31*INDEX('Допущения A'!$C$25:$G$31,MATCH($C31,'Допущения A'!$B$25:$B$31,0),3)) -> 72000 | H31: =IF($D31="","",$D31*INDEX('Допущения A'!$C$25:$G$31,MATCH($C31,'Допущения A'!$B$25:$B$31,0),4)) -> 132000 | I31: =IF($D31="","",$D31*INDEX('Допущения A'!$C$25:$G$31,MATCH($C31,'Допущения A'!$B$25:$B$31,0),5)) -> 216000 | J31: =SUM(E31:I31) -> 456000 | L31: USSD-сессии: 20% заказов × 3 сессии × $0,02
B32: Итого по блоку | E32: =SUM(E27:E31) -> 388200 | F32: =SUM(F27:F31) -> 1608000 | G32: =SUM(G27:G31) -> 4158000 | H32: =SUM(H27:H31) -> 7876000 | I32: =SUM(I27:I31) -> 13302000 | J32: =SUM(J27:J31) -> 27332200 | K32: =IFERROR(J32/$J$51,0) -> 0.63882425
B34: БЛОК 4. Команда (ФОТ)
B35: Разработка (FTE × годовая ставка) | C35: ФОТ | D35: 330000 | E35: =5*66000*INDEX('Допущения A'!$C$25:$G$31,MATCH("ФОТ",'Допущения A'!$B$25:$B$31,0),1) -> 330000 | F35: =8*66000*INDEX('Допущения A'!$C$25:$G$31,MATCH("ФОТ",'Допущения A'!$B$25:$B$31,0),2) -> 591360 | G35: =12*66000*INDEX('Допущения A'!$C$25:$G$31,MATCH("ФОТ",'Допущения A'!$B$25:$B$31,0),3) -> 993484.8 | H35: =15*66000*INDEX('Допущения A'!$C$25:$G$31,MATCH("ФОТ",'Допущения A'!$B$25:$B$31,0),4) -> 1390878.7 | I35: =18*66000*INDEX('Допущения A'!$C$25:$G$31,MATCH("ФОТ",'Допущения A'!$B$25:$B$31,0),5) -> 1869341 | J35: =SUM(E35:I35) -> 5175064.5 | L35: Go-разработчики: 5 из 6 контракторов (A6 п.5) рост по roadmap. FTE по годам: 5/8/12/15/18 × $66 000
B36: DevOps / SRE | C36: ФОТ | D36: 78000 | E36: =1*78000*INDEX('Допущения A'!$C$25:$G$31,MATCH("ФОТ",'Допущения A'!$B$25:$B$31,0),1) -> 78000 | F36: =2*78000*INDEX('Допущения A'!$C$25:$G$31,MATCH("ФОТ",'Допущения A'!$B$25:$B$31,0),2) -> 174720 | G36: =3*78000*INDEX('Допущения A'!$C$25:$G$31,MATCH("ФОТ",'Допущения A'!$B$25:$B$31,0),3) -> 293529.6 | H36: =3*78000*INDEX('Допущения A'!$C$25:$G$31,MATCH("ФОТ",'Допущения A'!$B$25:$B$31,0),4) -> 328753.15 | I36: =4*78000*INDEX('Допущения A'!$C$25:$G$31,MATCH("ФОТ",'Допущения A'!$B$25:$B$31,0),5) -> 490938.04 | J36: =SUM(E36:I36) -> 1365940.8 | L36: DevOps/SRE: 1 на запуске. FTE по годам: 1/2/3/3/4 × $78 000
B37: Поддержка и дежурства 24/7 | C37: ФОТ | D37: 24000 | E37: =0.5*48000*INDEX('Допущения A'!$C$25:$G$31,MATCH("ФОТ",'Допущения A'!$B$25:$B$31,0),1) -> 24000 | F37: =1*48000*INDEX('Допущения A'!$C$25:$G$31,MATCH("ФОТ",'Допущения A'!$B$25:$B$31,0),2) -> 53760 | G37: =2*48000*INDEX('Допущения A'!$C$25:$G$31,MATCH("ФОТ",'Допущения A'!$B$25:$B$31,0),3) -> 120422.4 | H37: =2*48000*INDEX('Допущения A'!$C$25:$G$31,MATCH("ФОТ",'Допущения A'!$B$25:$B$31,0),4) -> 134873.09 | I37: =3*48000*INDEX('Допущения A'!$C$25:$G$31,MATCH("ФОТ",'Допущения A'!$B$25:$B$31,0),5) -> 226586.79 | J37: =SUM(E37:I37) -> 559642.28 | L37: Дежурства: on-call ротация + L1 (без 24/7 SRE). FTE по годам: 0.5/1/2/2/3 × $48 000
B38: Архитектура и менеджмент | C38: ФОТ | D38: 240000 | E38: =IF($D38="","",$D38*INDEX('Допущения A'!$C$25:$G$31,MATCH($C38,'Допущения A'!$B$25:$B$31,0),1)) -> 240000 | F38: =IF($D38="","",$D38*INDEX('Допущения A'!$C$25:$G$31,MATCH($C38,'Допущения A'!$B$25:$B$31,0),2)) -> 268800 | G38: =IF($D38="","",$D38*INDEX('Допущения A'!$C$25:$G$31,MATCH($C38,'Допущения A'!$B$25:$B$31,0),3)) -> 301056 | H38: =IF($D38="","",$D38*INDEX('Допущения A'!$C$25:$G$31,MATCH($C38,'Допущения A'!$B$25:$B$31,0),4)) -> 337182.72 | I38: =IF($D38="","",$D38*INDEX('Допущения A'!$C$25:$G$31,MATCH($C38,'Допущения A'!$B$25:$B$31,0),5)) -> 377644.65 | J38: =SUM(E38:I38) -> 1524683.4 | L38: CTO, архитектор, PM - одинаково для всех вариантов
C39: фикс | E39: =IF($D39="","",$D39*INDEX('Допущения A'!$C$25:$G$31,MATCH($C39,'Допущения A'!$B$25:$B$31,0),1)) | F39: =IF($D39="","",$D39*INDEX('Допущения A'!$C$25:$G$31,MATCH($C39,'Допущения A'!$B$25:$B$31,0),2)) | G39: =IF($D39="","",$D39*INDEX('Допущения A'!$C$25:$G$31,MATCH($C39,'Допущения A'!$B$25:$B$31,0),3)) | H39: =IF($D39="","",$D39*INDEX('Допущения A'!$C$25:$G$31,MATCH($C39,'Допущения A'!$B$25:$B$31,0),4)) | I39: =IF($D39="","",$D39*INDEX('Допущения A'!$C$25:$G$31,MATCH($C39,'Допущения A'!$B$25:$B$31,0),5)) | J39: =SUM(E39:I39) -> 0 | L39: Своя статья
B40: Итого по блоку | E40: =SUM(E35:E39) -> 672000 | F40: =SUM(F35:F39) -> 1088640 | G40: =SUM(G35:G39) -> 1708492.8 | H40: =SUM(H35:H39) -> 2191687.7 | I40: =SUM(I35:I39) -> 2964510.5 | J40: =SUM(J35:J39) -> 8625331 | K40: =IFERROR(J40/$J$51,0) -> 0.20159631
B42: БЛОК 5. Разовые затраты и комплаенс
B43: Юридический и комплаенс-аудит (NDPR, POPIA, KICA) | C43: фикс | D43: 25000 | E43: 25000 | F43: 10000 | G43: 10000 | H43: 10000 | I43: 10000 | J43: =SUM(E43:I43) -> 65000 | L43: Аудит NDPR/POPIA/KDPA; далее ежегодный audit return NDPC (A3 п.1) (годы 2–5 перезаписаны вручную, как требует инструкция C25)
B44: Пентест и аудит безопасности | C44: инфляция | D44: 15000 | E44: =IF($D44="","",$D44*INDEX('Допущения A'!$C$25:$G$31,MATCH($C44,'Допущения A'!$B$25:$B$31,0),1)) -> 15000 | F44: =IF($D44="","",$D44*INDEX('Допущения A'!$C$25:$G$31,MATCH($C44,'Допущения A'!$B$25:$B$31,0),2)) -> 16200 | G44: =IF($D44="","",$D44*INDEX('Допущения A'!$C$25:$G$31,MATCH($C44,'Допущения A'!$B$25:$B$31,0),3)) -> 17496 | H44: =IF($D44="","",$D44*INDEX('Допущения A'!$C$25:$G$31,MATCH($C44,'Допущения A'!$B$25:$B$31,0),4)) -> 18895.68 | I44: =IF($D44="","",$D44*INDEX('Допущения A'!$C$25:$G$31,MATCH($C44,'Допущения A'!$B$25:$B$31,0),5)) -> 20407.334 | J44: =SUM(E44:I44) -> 87999.014 | L44: Пентест ежегодно
B45: Миграция данных и интеграции при запуске | C45: фикс | D45: 20000 | E45: =$D45 -> 20000 | F45: 0 | G45: 0 | H45: 0 | I45: 0 | J45: =SUM(E45:I45) -> 20000 | L45: Интеграции PSP/логистики, сертификация у провайдеров - разовая, годы 2–5 обнулены вручную
B46: Обучение команды и найм | C46: ФОТ | D46: 10000 | E46: =IF($D46="","",$D46*INDEX('Допущения A'!$C$25:$G$31,MATCH($C46,'Допущения A'!$B$25:$B$31,0),1)) -> 10000 | F46: =IF($D46="","",$D46*INDEX('Допущения A'!$C$25:$G$31,MATCH($C46,'Допущения A'!$B$25:$B$31,0),2)) -> 11200 | G46: =IF($D46="","",$D46*INDEX('Допущения A'!$C$25:$G$31,MATCH($C46,'Допущения A'!$B$25:$B$31,0),3)) -> 12544 | H46: =IF($D46="","",$D46*INDEX('Допущения A'!$C$25:$G$31,MATCH($C46,'Допущения A'!$B$25:$B$31,0),4)) -> 14049.28 | I46: =IF($D46="","",$D46*INDEX('Допущения A'!$C$25:$G$31,MATCH($C46,'Допущения A'!$B$25:$B$31,0),5)) -> 15735.194 | J46: =SUM(E46:I46) -> 63528.474 | L46: Онбординг контракторов; найм заморожен до декабря (A6 п.5)
...

Sheet Допущения B
B2: Допущения модели TCO - вариант B: Сервисная архитектура (6 сервисов)
B3: Заполняются только ячейки с жёлтой заливкой. Все числа ниже - пример, заменить своими.
B5: 1. Драйверы бизнеса - заполнить
B6: Показатель | C6: Год 1 | D6: Год 2 | E6: Год 3 | F6: Год 4 | G6: Год 5 | H6: Комментарий / источник
B7: Активные пользователи (на конец года) | C7: ='Допущения A'!C7 -> 400000 | D7: ='Допущения A'!D7 -> 1200000 | E7: ='Допущения A'!E7 -> 2500000 | F7: ='Допущения A'!F7 -> 4000000 | G7: ='Допущения A'!G7 -> 6000000 | H7: Ссылка на «Допущения A» - единые драйверы для всех вариантов
B8: Число заказов в год | C8: ='Допущения A'!C8 -> 600000 | D8: ='Допущения A'!D8 -> 2400000 | E8: ='Допущения A'!E8 -> 6000000 | F8: ='Допущения A'!F8 -> 11000000 | G8: ='Допущения A'!G8 -> 18000000 | H8: Ссылка на «Допущения A» - единые драйверы для всех вариантов
B9: Средний чек (AOV), $ | C9: ='Допущения A'!C9 -> 20 | D9: ='Допущения A'!D9 -> 21 | E9: ='Допущения A'!E9 -> 22 | F9: ='Допущения A'!F9 -> 23 | G9: ='Допущения A'!G9 -> 24 | H9: Ссылка на «Допущения A» - единые драйверы для всех вариантов
B10: GMV, $ в год (расчёт) | C10: =C8*C9 -> 12000000 | D10: =D8*D9 -> 50400000 | E10: =E8*E9 -> 132000000 | F10: =F8*F9 -> 253000000 | G10: =G8*G9 -> 432000000 | H10: Расчёт: заказы × средний чек
B12: 2. Финансовые допущения - заполнить
B13: Параметр | C13: Значение | H13: Комментарий / источник
B14: Инфляция затрат, % в год | C14: 0.08 | H14: Применяется к статьям с драйвером «инфляция»
B15: Рост ФОТ, % в год | C15: 0.12 | H15: Дефицит ИТ-специалистов на рынке - рост выше инфляции
B16: Ставка дисконтирования, % в год | C16: 0.2 | H16: Для расчёта NPV затрат. Стартап, высокий риск
B17: Резерв на непредвиденное (contingency), % | C17: 0.15 | H17: Надбавка к прямым затратам
B18: Бюджет CFO на облако, $/мес | C18: 5000 | H18: A6 п.1: $5 000/мес - жёсткий потолок, включая мониторинг и SaaS. $9 000 - цифра из board deck, разработке недоступна
B19: Стоимость минуты простоя, $ | C19: 12000 | H19: Оценка инвестора «в распродажу» (A1, A7). В блоке 6 минута считается от GMV, плоские $12k - на листе «Сравнение»
B20: Целевой SLO (доступность), % | C20: 0.9995 | H20: Warm standby
B21: Учитывать стоимость простоя в TCO (1 - да, 0 - нет) | C21: 1 | H21: Переключатель для сценарного анализа
B22: Коэффициент пиковости простоя (× к средней GMV/мин) | C22: 5 | H22: Сбои концентрируются в часы пик и распродаж
B23: 3. Индексы роста - расчёт, не редактировать
B24: Драйвер | C24: Год 1 | D24: Год 2 | E24: Год 3 | F24: Год 4 | G24: Год 5 | H24: Как считается
B25: фикс | C25: 1 | D25: 1 | E25: 1 | F25: 1 | G25: 1 | H25: Затраты не меняются по годам
B26: инфляция | C26: 1 | D26: =C26*(1+$C$14) -> 1.08 | E26: =D26*(1+$C$14) -> 1.1664 | F26: =E26*(1+$C$14) -> 1.259712 | G26: =F26*(1+$C$14) -> 1.360489 | H26: Год N = Год N-1 × (1 + инфляция)
B27: ФОТ | C27: 1 | D27: =C27*(1+$C$15) -> 1.12 | E27: =D27*(1+$C$15) -> 1.2544 | F27: =E27*(1+$C$15) -> 1.404928 | G27: =F27*(1+$C$15) -> 1.5735194 | H27: Год N = Год N-1 × (1 + рост ФОТ)
B28: пользователи | C28: =C7/$C$7 -> 1 | D28: =D7/$C$7 -> 3 | E28: =E7/$C$7 -> 6.25 | F28: =F7/$C$7 -> 10 | G28: =G7/$C$7 -> 15 | H28: Пропорционально числу активных пользователей
B29: заказы | C29: =C8/$C$8 -> 1 | D29: =D8/$C$8 -> 4 | E29: =E8/$C$8 -> 10 | F29: =F8/$C$8 -> 18.333333 | G29: =G8/$C$8 -> 30 | H29: Пропорционально числу заказов
B30: GMV | C30: =C10/$C$10 -> 1 | D30: =D10/$C$10 -> 4.2 | E30: =E10/$C$10 -> 11 | F30: =F10/$C$10 -> 21.083333 | G30: =G10/$C$10 -> 36 | H30: Пропорционально обороту
B31: масштаб | C31: =(C7/$C$7)^0.7 -> 1 | D31: =(D7/$C$7)^0.7 -> 2.1576693 | E31: =(E7/$C$7)^0.7 -> 3.6067498 | F31: =(F7/$C$7)^0.7 -> 5.0118723 | G31: =(G7/$C$7)^0.7 -> 6.6567751 | H31: Сублинейный рост инфраструктуры: (пользователи)^0,7 - эффект масштаба (см. примечание B32)
B32: Драйвер «пользователи» - упрощение: облачные расходы редко растут строго линейно (есть эффект масштаба и обратный эффект - рост нагрузки на БД). При желании введи свой драйвер отдельной строкой в таблице индексов.
B33: Драйвер «масштаб» добавлен по рекомендации B32; все варианты используют одинаковые драйверы.

Sheet TCO B
B2: TCO на 5 лет - вариант B: Сервисная архитектура (6 сервисов)
B3: Заполняем колонки «Драйвер роста» и «База, $/год (Год 1)». Годы 1–5 считаются автоматически.
B5: Статья затрат | C5: Драйвер роста | D5: База, $/год (Год 1) | E5: Год 1 | F5: Год 2 | G5: Год 3 | H5: Год 4 | I5: Год 5 | J5: Итого 5 лет | K5: Доля | L5: Комментарий / источник
B6: БЛОК 1. Облачная инфраструктура (OpEx)
B7: Compute: ноды / контейнеры / serverless | C7: масштаб | D7: 24000 | E7: =IF($D7="","",$D7*INDEX('Допущения B'!$C$25:$G$31,MATCH($C7,'Допущения B'!$B$25:$B$31,0),1)) -> 24000 | F7: =IF($D7="","",$D7*INDEX('Допущения B'!$C$25:$G$31,MATCH($C7,'Допущения B'!$B$25:$B$31,0),2)) -> 51784.063 | G7: =IF($D7="","",$D7*INDEX('Допущения B'!$C$25:$G$31,MATCH($C7,'Допущения B'!$B$25:$B$31,0),3)) -> 86561.994 | H7: =IF($D7="","",$D7*INDEX('Допущения B'!$C$25:$G$31,MATCH($C7,'Допущения B'!$B$25:$B$31,0),4)) -> 120284.94 | I7: =IF($D7="","",$D7*INDEX('Допущения B'!$C$25:$G$31,MATCH($C7,'Допущения B'!$B$25:$B$31,0),5)) -> 159762.6 | J7: =SUM(E7:I7) -> 442393.59 | L7: 6 сервисов × 2 страны, sidecar-оверхед, gateway. ~$2 000/мес
B8: Управляемые БД (PostgreSQL, реплики) | C8: масштаб | D8: 18000 | E8: =IF($D8="","",$D8*INDEX('Допущения B'!$C$25:$G$31,MATCH($C8,'Допущения B'!$B$25:$B$31,0),1)) -> 18000 | F8: =IF($D8="","",$D8*INDEX('Допущения B'!$C$25:$G$31,MATCH($C8,'Допущения B'!$B$25:$B$31,0),2)) -> 38838.047 | G8: =IF($D8="","",$D8*INDEX('Допущения B'!$C$25:$G$31,MATCH($C8,'Допущения B'!$B$25:$B$31,0),3)) -> 64921.496 | H8: =IF($D8="","",$D8*INDEX('Допущения B'!$C$25:$G$31,MATCH($C8,'Допущения B'!$B$25:$B$31,0),4)) -> 90213.702 | I8: =IF($D8="","",$D8*INDEX('Допущения B'!$C$25:$G$31,MATCH($C8,'Допущения B'!$B$25:$B$31,0),5)) -> 119821.95 | J8: =SUM(E8:I8) -> 331795.2 | L8: Managed PostgreSQL на сервис (3 инстанса × 2 страны)
B9: Хранилище объектов и резервные копии | C9: пользователи | D9: 2400 | E9: =IF($D9="","",$D9*INDEX('Допущения B'!$C$25:$G$31,MATCH($C9,'Допущения B'!$B$25:$B$31,0),1)) -> 2400 | F9: =IF($D9="","",$D9*INDEX('Допущения B'!$C$25:$G$31,MATCH($C9,'Допущения B'!$B$25:$B$31,0),2)) -> 7200 | G9: =IF($D9="","",$D9*INDEX('Допущения B'!$C$25:$G$31,MATCH($C9,'Допущения B'!$B$25:$B$31,0),3)) -> 15000 | H9: =IF($D9="","",$D9*INDEX('Допущения B'!$C$25:$G$31,MATCH($C9,'Допущения B'!$B$25:$B$31,0),4)) -> 24000 | I9: =IF($D9="","",$D9*INDEX('Допущения B'!$C$25:$G$31,MATCH($C9,'Допущения B'!$B$25:$B$31,0),5)) -> 36000 | J9: =SUM(E9:I9) -> 84600 | L9: Как в A
B10: CDN и исходящий трафик | C10: пользователи | D10: 6000 | E10: =IF($D10="","",$D10*INDEX('Допущения B'!$C$25:$G$31,MATCH($C10,'Допущения B'!$B$25:$B$31,0),1)) -> 6000 | F10: =IF($D10="","",$D10*INDEX('Допущения B'!$C$25:$G$31,MATCH($C10,'Допущения B'!$B$25:$B$31,0),2)) -> 18000 | G10: =IF($D10="","",$D10*INDEX('Допущения B'!$C$25:$G$31,MATCH($C10,'Допущения B'!$B$25:$B$31,0),3)) -> 37500 | H10: =IF($D10="","",$D10*INDEX('Допущения B'!$C$25:$G$31,MATCH($C10,'Допущения B'!$B$25:$B$31,0),4)) -> 60000 | I10: =IF($D10="","",$D10*INDEX('Допущения B'!$C$25:$G$31,MATCH($C10,'Допущения B'!$B$25:$B$31,0),5)) -> 90000 | J10: =SUM(E10:I10) -> 211500 | L10: Как в A
B11: Очереди / стриминг (Kafka, SQS) | C11: масштаб | D11: 9600 | E11: =IF($D11="","",$D11*INDEX('Допущения B'!$C$25:$G$31,MATCH($C11,'Допущения B'!$B$25:$B$31,0),1)) -> 9600 | F11: =IF($D11="","",$D11*INDEX('Допущения B'!$C$25:$G$31,MATCH($C11,'Допущения B'!$B$25:$B$31,0),2)) -> 20713.625 | G11: =IF($D11="","",$D11*INDEX('Допущения B'!$C$25:$G$31,MATCH($C11,'Допущения B'!$B$25:$B$31,0),3)) -> 34624.798 | H11: =IF($D11="","",$D11*INDEX('Допущения B'!$C$25:$G$31,MATCH($C11,'Допущения B'!$B$25:$B$31,0),4)) -> 48113.974 | I11: =IF($D11="","",$D11*INDEX('Допущения B'!$C$25:$G$31,MATCH($C11,'Допущения B'!$B$25:$B$31,0),5)) -> 63905.04 | J11: =SUM(E11:I11) -> 176957.44 | L11: Managed Kafka-совместимый брокер (2 кластера × ~$400/мес)
B12: Резервный регион / DR | C12: инфляция | D12: 18000 | E12: =IF($D12="","",$D12*INDEX('Допущения B'!$C$25:$G$31,MATCH($C12,'Допущения B'!$B$25:$B$31,0),1)) -> 18000 | F12: =IF($D12="","",$D12*INDEX('Допущения B'!$C$25:$G$31,MATCH($C12,'Допущения B'!$B$25:$B$31,0),2)) -> 19440 | G12: =IF($D12="","",$D12*INDEX('Допущения B'!$C$25:$G$31,MATCH($C12,'Допущения B'!$B$25:$B$31,0),3)) -> 20995.2 | H12: =IF($D12="","",$D12*INDEX('Допущения B'!$C$25:$G$31,MATCH($C12,'Допущения B'!$B$25:$B$31,0),4)) -> 22674.816 | I12: =IF($D12="","",$D12*INDEX('Допущения B'!$C$25:$G$31,MATCH($C12,'Допущения B'!$B$25:$B$31,0),5)) -> 24488.801 | J12: =SUM(E12:I12) -> 105598.82 | L12: Warm standby во втором ЦОДе страны, RTO ≤ 30 мин
B13: Локальное размещение данных (NDPR, Нигерия) | C13: инфляция | D13: 12000 | E13: =IF($D13="","",$D13*INDEX('Допущения B'!$C$25:$G$31,MATCH($C13,'Допущения B'!$B$25:$B$31,0),1)) -> 12000 | F13: =IF($D13="","",$D13*INDEX('Допущения B'!$C$25:$G$31,MATCH($C13,'Допущения B'!$B$25:$B$31,0),2)) -> 12960 | G13: =IF($D13="","",$D13*INDEX('Допущения B'!$C$25:$G$31,MATCH($C13,'Допущения B'!$B$25:$B$31,0),3)) -> 13996.8 | H13: =IF($D13="","",$D13*INDEX('Допущения B'!$C$25:$G$31,MATCH($C13,'Допущения B'!$B$25:$B$31,0),4)) -> 15116.544 | I13: =IF($D13="","",$D13*INDEX('Допущения B'!$C$25:$G$31,MATCH($C13,'Допущения B'!$B$25:$B$31,0),5)) -> 16325.868 | J13: =SUM(E13:I13) -> 70399.212 | L13: Как в A
C14: фикс | E14: =IF($D14="","",$D14*INDEX('Допущения B'!$C$25:$G$31,MATCH($C14,'Допущения B'!$B$25:$B$31,0),1)) | F14: =IF($D14="","",$D14*INDEX('Допущения B'!$C$25:$G$31,MATCH($C14,'Допущения B'!$B$25:$B$31,0),2)) | G14: =IF($D14="","",$D14*INDEX('Допущения B'!$C$25:$G$31,MATCH($C14,'Допущения B'!$B$25:$B$31,0),3)) | H14: =IF($D14="","",$D14*INDEX('Допущения B'!$C$25:$G$31,MATCH($C14,'Допущения B'!$B$25:$B$31,0),4)) | I14: =IF($D14="","",$D14*INDEX('Допущения B'!$C$25:$G$31,MATCH($C14,'Допущения B'!$B$25:$B$31,0),5)) | J14: =SUM(E14:I14) -> 0 | L14: Своя статья
B15: Итого по блоку | E15: =SUM(E7:E14) -> 90000 | F15: =SUM(F7:F14) -> 168935.73 | G15: =SUM(G7:G14) -> 273600.29 | H15: =SUM(H7:H14) -> 380403.97 | I15: =SUM(I7:I14) -> 510304.26 | J15: =SUM(J7:J14) -> 1423244.3 | K15: =IFERROR(J15/$J$51,0) -> 0.031392324
B17: БЛОК 2. Лицензии, SaaS и инструменты
B18: Observability (метрики, логи, трейсинг) | C18: масштаб | D18: 6000 | E18: =IF($D18="","",$D18*INDEX('Допущения B'!$C$25:$G$31,MATCH($C18,'Допущения B'!$B$25:$B$31,0),1)) -> 6000 | F18: =IF($D18="","",$D18*INDEX('Допущения B'!$C$25:$G$31,MATCH($C18,'Допущения B'!$B$25:$B$31,0),2)) -> 12946.016 | G18: =IF($D18="","",$D18*INDEX('Допущения B'!$C$25:$G$31,MATCH($C18,'Допущения B'!$B$25:$B$31,0),3)) -> 21640.499 | H18: =IF($D18="","",$D18*INDEX('Допущения B'!$C$25:$G$31,MATCH($C18,'Допущения B'!$B$25:$B$31,0),4)) -> 30071.234 | I18: =IF($D18="","",$D18*INDEX('Допущения B'!$C$25:$G$31,MATCH($C18,'Допущения B'!$B$25:$B$31,0),5)) -> 39940.65 | J18: =SUM(E18:I18) -> 110598.4 | L18: OSS-стек, но ×3 объём телеметрии (распределённые трассы)
B19: CI/CD, репозиторий, артефакты | C19: инфляция | D19: 3000 | E19: =IF($D19="","",$D19*INDEX('Допущения B'!$C$25:$G$31,MATCH($C19,'Допущения B'!$B$25:$B$31,0),1)) -> 3000 | F19: =IF($D19="","",$D19*INDEX('Допущения B'!$C$25:$G$31,MATCH($C19,'Допущения B'!$B$25:$B$31,0),2)) -> 3240 | G19: =IF($D19="","",$D19*INDEX('Допущения B'!$C$25:$G$31,MATCH($C19,'Допущения B'!$B$25:$B$31,0),3)) -> 3499.2 | H19: =IF($D19="","",$D19*INDEX('Допущения B'!$C$25:$G$31,MATCH($C19,'Допущения B'!$B$25:$B$31,0),4)) -> 3779.136 | I19: =IF($D19="","",$D19*INDEX('Допущения B'!$C$25:$G$31,MATCH($C19,'Допущения B'!$B$25:$B$31,0),5)) -> 4081.4669 | J19: =SUM(E19:I19) -> 17599.803 | L19: CI/CD на 6 пайплайнов
B20: Безопасность: WAF, секреты, антифрод | C20: пользователи | D20: 2400 | E20: =IF($D20="","",$D20*INDEX('Допущения B'!$C$25:$G$31,MATCH($C20,'Допущения B'!$B$25:$B$31,0),1)) -> 2400 | F20: =IF($D20="","",$D20*INDEX('Допущения B'!$C$25:$G$31,MATCH($C20,'Допущения B'!$B$25:$B$31,0),2)) -> 7200 | G20: =IF($D20="","",$D20*INDEX('Допущения B'!$C$25:$G$31,MATCH($C20,'Допущения B'!$B$25:$B$31,0),3)) -> 15000 | H20: =IF($D20="","",$D20*INDEX('Допущения B'!$C$25:$G$31,MATCH($C20,'Допущения B'!$B$25:$B$31,0),4)) -> 24000 | I20: =IF($D20="","",$D20*INDEX('Допущения B'!$C$25:$G$31,MATCH($C20,'Допущения B'!$B$25:$B$31,0),5)) -> 36000 | J20: =SUM(E20:I20) -> 84600 | L20: Как в A
B21: WhatsApp Business API (подписка) | C21: инфляция | D21: 1200 | E21: =IF($D21="","",$D21*INDEX('Допущения B'!$C$25:$G$31,MATCH($C21,'Допущения B'!$B$25:$B$31,0),1)) -> 1200 | F21: =IF($D21="","",$D21*INDEX('Допущения B'!$C$25:$G$31,MATCH($C21,'Допущения B'!$B$25:$B$31,0),2)) -> 1296 | G21: =IF($D21="","",$D21*INDEX('Допущения B'!$C$25:$G$31,MATCH($C21,'Допущения B'!$B$25:$B$31,0),3)) -> 1399.68 | H21: =IF($D21="","",$D21*INDEX('Допущения B'!$C$25:$G$31,MATCH($C21,'Допущения B'!$B$25:$B$31,0),4)) -> 1511.6544 | I21: =IF($D21="","",$D21*INDEX('Допущения B'!$C$25:$G$31,MATCH($C21,'Допущения B'!$B$25:$B$31,0),5)) -> 1632.5868 | J21: =SUM(E21:I21) -> 7039.9212 | L21: Как в A
B22: Прочее ПО и подписки | C22: инфляция | D22: 1200 | E22: =IF($D22="","",$D22*INDEX('Допущения B'!$C$25:$G$31,MATCH($C22,'Допущения B'!$B$25:$B$31,0),1)) -> 1200 | F22: =IF($D22="","",$D22*INDEX('Допущения B'!$C$25:$G$31,MATCH($C22,'Допущения B'!$B$25:$B$31,0),2)) -> 1296 | G22: =IF($D22="","",$D22*INDEX('Допущения B'!$C$25:$G$31,MATCH($C22,'Допущения B'!$B$25:$B$31,0),3)) -> 1399.68 | H22: =IF($D22="","",$D22*INDEX('Допущения B'!$C$25:$G$31,MATCH($C22,'Допущения B'!$B$25:$B$31,0),4)) -> 1511.6544 | I22: =IF($D22="","",$D22*INDEX('Допущения B'!$C$25:$G$31,MATCH($C22,'Допущения B'!$B$25:$B$31,0),5)) -> 1632.5868 | J22: =SUM(E22:I22) -> 7039.9212 | L22: Как в A
C23: фикс | E23: =IF($D23="","",$D23*INDEX('Допущения B'!$C$25:$G$31,MATCH($C23,'Допущения B'!$B$25:$B$31,0),1)) | F23: =IF($D23="","",$D23*INDEX('Допущения B'!$C$25:$G$31,MATCH($C23,'Допущения B'!$B$25:$B$31,0),2)) | G23: =IF($D23="","",$D23*INDEX('Допущения B'!$C$25:$G$31,MATCH($C23,'Допущения B'!$B$25:$B$31,0),3)) | H23: =IF($D23="","",$D23*INDEX('Допущения B'!$C$25:$G$31,MATCH($C23,'Допущения B'!$B$25:$B$31,0),4)) | I23: =IF($D23="","",$D23*INDEX('Допущения B'!$C$25:$G$31,MATCH($C23,'Допущения B'!$B$25:$B$31,0),5)) | J23: =SUM(E23:I23) -> 0 | L23: Своя статья
B24: Итого по блоку | E24: =SUM(E18:E23) -> 13800 | F24: =SUM(F18:F23) -> 25978.016 | G24: =SUM(G18:G23) -> 42939.059 | H24: =SUM(H18:H23) -> 60873.679 | I24: =SUM(I18:I23) -> 83287.291 | J24: =SUM(J18:J23) -> 226878.04 | K24: =IFERROR(J24/$J$51,0) -> 0.0050042212
B26: БЛОК 3. Транзакционные расходы (Buy / Partner)
B27: Комиссии платёжных провайдеров | C27: GMV | D27: ='Допущения B'!C10*0.023 -> 276000 | E27: =IF($D27="","",$D27*INDEX('Допущения B'!$C$25:$G$31,MATCH($C27,'Допущения B'!$B$25:$B$31,0),1)) -> 276000 | F27: =IF($D27="","",$D27*INDEX('Допущения B'!$C$25:$G$31,MATCH($C27,'Допущения B'!$B$25:$B$31,0),2)) -> 1159200 | G27: =IF($D27="","",$D27*INDEX('Допущения B'!$C$25:$G$31,MATCH($C27,'Допущения B'!$B$25:$B$31,0),3)) -> 3036000 | H27: =IF($D27="","",$D27*INDEX('Допущения B'!$C$25:$G$31,MATCH($C27,'Допущения B'!$B$25:$B$31,0),4)) -> 5819000 | I27: =IF($D27="","",$D27*INDEX('Допущения B'!$C$25:$G$31,MATCH($C27,'Допущения B'!$B$25:$B$31,0),5)) -> 9936000 | J27: =SUM(E27:I27) -> 20226200 | L27: Комиссии PSP 2,3% GMV (лимит CFO 2,5%, A6 п.6): M-Pesa, Flutterwave, Paystack
B28: SMS-уведомления | C28: заказы | D28: 36000 | E28: =IF($D28="","",$D28*INDEX('Допущения B'!$C$25:$G$31,MATCH($C28,'Допущения B'!$B$25:$B$31,0),1)) -> 36000 | F28: =IF($D28="","",$D28*INDEX('Допущения B'!$C$25:$G$31,MATCH($C28,'Допущения B'!$B$25:$B$31,0),2)) -> 144000 | G28: =IF($D28="","",$D28*INDEX('Допущения B'!$C$25:$G$31,MATCH($C28,'Допущения B'!$B$25:$B$31,0),3)) -> 360000 | H28: =IF($D28="","",$D28*INDEX('Допущения B'!$C$25:$G$31,MATCH($C28,'Допущения B'!$B$25:$B$31,0),4)) -> 660000 | I28: =IF($D28="","",$D28*INDEX('Допущения B'!$C$25:$G$31,MATCH($C28,'Допущения B'!$B$25:$B$31,0),5)) -> 1080000 | J28: =SUM(E28:I28) -> 2280000 | L28: SMS: 3 транзакционных SMS на заказ × $0,02 (только opt-in, C-08)
B29: WhatsApp-сообщения (за диалог) | C29: заказы | D29: 9000 | E29: =IF($D29="","",$D29*INDEX('Допущения B'!$C$25:$G$31,MATCH($C29,'Допущения B'!$B$25:$B$31,0),1)) -> 9000 | F29: =IF($D29="","",$D29*INDEX('Допущения B'!$C$25:$G$31,MATCH($C29,'Допущения B'!$B$25:$B$31,0),2)) -> 36000 | G29: =IF($D29="","",$D29*INDEX('Допущения B'!$C$25:$G$31,MATCH($C29,'Допущения B'!$B$25:$B$31,0),3)) -> 90000 | H29: =IF($D29="","",$D29*INDEX('Допущения B'!$C$25:$G$31,MATCH($C29,'Допущения B'!$B$25:$B$31,0),4)) -> 165000 | I29: =IF($D29="","",$D29*INDEX('Допущения B'!$C$25:$G$31,MATCH($C29,'Допущения B'!$B$25:$B$31,0),5)) -> 270000 | J29: =SUM(E29:I29) -> 570000 | L29: WhatsApp: 0,5 utility-диалога на заказ × $0,03
B30: Логистика: интеграции и комиссии партнёров | C30: заказы | D30: 60000 | E30: =IF($D30="","",$D30*INDEX('Допущения B'!$C$25:$G$31,MATCH($C30,'Допущения B'!$B$25:$B$31,0),1)) -> 60000 | F30: =IF($D30="","",$D30*INDEX('Допущения B'!$C$25:$G$31,MATCH($C30,'Допущения B'!$B$25:$B$31,0),2)) -> 240000 | G30: =IF($D30="","",$D30*INDEX('Допущения B'!$C$25:$G$31,MATCH($C30,'Допущения B'!$B$25:$B$31,0),3)) -> 600000 | H30: =IF($D30="","",$D30*INDEX('Допущения B'!$C$25:$G$31,MATCH($C30,'Допущения B'!$B$25:$B$31,0),4)) -> 1100000 | I30: =IF($D30="","",$D30*INDEX('Допущения B'!$C$25:$G$31,MATCH($C30,'Допущения B'!$B$25:$B$31,0),5)) -> 1800000 | J30: =SUM(E30:I30) -> 3800000 | L30: Платформенный сбор Sendbox/Sendy $0,10 за отправление (доставку оплачивает покупатель)
B31: USSD-шлюз (сессии) | C31: заказы | D31: 7200 | E31: =IF($D31="","",$D31*INDEX('Допущения B'!$C$25:$G$31,MATCH($C31,'Допущения B'!$B$25:$B$31,0),1)) -> 7200 | F31: =IF($D31="","",$D31*INDEX('Допущения B'!$C$25:$G$31,MATCH($C31,'Допущения B'!$B$25:$B$31,0),2)) -> 28800 | G31: =IF($D31="","",$D31*INDEX('Допущения B'!$C$25:$G$31,MATCH($C31,'Допущения B'!$B$25:$B$31,0),3)) -> 72000 | H31: =IF($D31="","",$D31*INDEX('Допущения B'!$C$25:$G$31,MATCH($C31,'Допущения B'!$B$25:$B$31,0),4)) -> 132000 | I31: =IF($D31="","",$D31*INDEX('Допущения B'!$C$25:$G$31,MATCH($C31,'Допущения B'!$B$25:$B$31,0),5)) -> 216000 | J31: =SUM(E31:I31) -> 456000 | L31: USSD-сессии: 20% заказов × 3 сессии × $0,02
B32: Итого по блоку | E32: =SUM(E27:E31) -> 388200 | F32: =SUM(F27:F31) -> 1608000 | G32: =SUM(G27:G31) -> 4158000 | H32: =SUM(H27:H31) -> 7876000 | I32: =SUM(I27:I31) -> 13302000 | J32: =SUM(J27:J31) -> 27332200 | K32: =IFERROR(J32/$J$51,0) -> 0.60286299
B34: БЛОК 4. Команда (ФОТ)
B35: Разработка (FTE × годовая ставка) | C35: ФОТ | D35: 462000 | E35: =7*66000*INDEX('Допущения B'!$C$25:$G$31,MATCH("ФОТ",'Допущения B'!$B$25:$B$31,0),1) -> 462000 | F35: =10*66000*INDEX('Допущения B'!$C$25:$G$31,MATCH("ФОТ",'Допущения B'!$B$25:$B$31,0),2) -> 739200 | G35: =14*66000*INDEX('Допущения B'!$C$25:$G$31,MATCH("ФОТ",'Допущения B'!$B$25:$B$31,0),3) -> 1159065.6 | H35: =17*66000*INDEX('Допущения B'!$C$25:$G$31,MATCH("ФОТ",'Допущения B'!$B$25:$B$31,0),4) -> 1576329.2 | I35: =20*66000*INDEX('Допущения B'!$C$25:$G$31,MATCH("ФОТ",'Допущения B'!$B$25:$B$31,0),5) -> 2077045.6 | J35: =SUM(E35:I35) -> 6013640.4 | L35: Нужно 7 разработчиков на старте → +2 сверх заморозки (нарушает A6 п.5). FTE по годам: 7/10/14/17/20 × $66 000
B36: DevOps / SRE | C36: ФОТ | D36: 156000 | E36: =2*78000*INDEX('Допущения B'!$C$25:$G$31,MATCH("ФОТ",'Допущения B'!$B$25:$B$31,0),1) -> 156000 | F36: =3*78000*INDEX('Допущения B'!$C$25:$G$31,MATCH("ФОТ",'Допущения B'!$B$25:$B$31,0),2) -> 262080 | G36: =4*78000*INDEX('Допущения B'!$C$25:$G$31,MATCH("ФОТ",'Допущения B'!$B$25:$B$31,0),3) -> 391372.8 | H36: =4*78000*INDEX('Допущения B'!$C$25:$G$31,MATCH("ФОТ",'Допущения B'!$B$25:$B$31,0),4) -> 438337.54 | I36: =5*78000*INDEX('Допущения B'!$C$25:$G$31,MATCH("ФОТ",'Допущения B'!$B$25:$B$31,0),5) -> 613672.55 | J36: =SUM(E36:I36) -> 1861462.9 | L36: Брокер gateway 6 пайплайнов. FTE по годам: 2/3/4/4/5 × $78 000
B37: Поддержка и дежурства 24/7 | C37: ФОТ | D37: 48000 | E37: =1*48000*INDEX('Допущения B'!$C$25:$G$31,MATCH("ФОТ",'Допущения B'!$B$25:$B$31,0),1) -> 48000 | F37: =2*48000*INDEX('Допущения B'!$C$25:$G$31,MATCH("ФОТ",'Допущения B'!$B$25:$B$31,0),2) -> 107520 | G37: =2*48000*INDEX('Допущения B'!$C$25:$G$31,MATCH("ФОТ",'Допущения B'!$B$25:$B$31,0),3) -> 120422.4 | H37: =3*48000*INDEX('Допущения B'!$C$25:$G$31,MATCH("ФОТ",'Допущения B'!$B$25:$B$31,0),4) -> 202309.63 | I37: =3*48000*INDEX('Допущения B'!$C$25:$G$31,MATCH("ФОТ",'Допущения B'!$B$25:$B$31,0),5) -> 226586.79 | J37: =SUM(E37:I37) -> 704838.82 | L37: Дежурства по сервисам. FTE по годам: 1/2/2/3/3 × $48 000
B38: Архитектура и менеджмент | C38: ФОТ | D38: 240000 | E38: =IF($D38="","",$D38*INDEX('Допущения B'!$C$25:$G$31,MATCH($C38,'Допущения B'!$B$25:$B$31,0),1)) -> 240000 | F38: =IF($D38="","",$D38*INDEX('Допущения B'!$C$25:$G$31,MATCH($C38,'Допущения B'!$B$25:$B$31,0),2)) -> 268800 | G38: =IF($D38="","",$D38*INDEX('Допущения B'!$C$25:$G$31,MATCH($C38,'Допущения B'!$B$25:$B$31,0),3)) -> 301056 | H38: =IF($D38="","",$D38*INDEX('Допущения B'!$C$25:$G$31,MATCH($C38,'Допущения B'!$B$25:$B$31,0),4)) -> 337182.72 | I38: =IF($D38="","",$D38*INDEX('Допущения B'!$C$25:$G$31,MATCH($C38,'Допущения B'!$B$25:$B$31,0),5)) -> 377644.65 | J38: =SUM(E38:I38) -> 1524683.4 | L38: Как в A
C39: фикс | E39: =IF($D39="","",$D39*INDEX('Допущения B'!$C$25:$G$31,MATCH($C39,'Допущения B'!$B$25:$B$31,0),1)) | F39: =IF($D39="","",$D39*INDEX('Допущения B'!$C$25:$G$31,MATCH($C39,'Допущения B'!$B$25:$B$31,0),2)) | G39: =IF($D39="","",$D39*INDEX('Допущения B'!$C$25:$G$31,MATCH($C39,'Допущения B'!$B$25:$B$31,0),3)) | H39: =IF($D39="","",$D39*INDEX('Допущения B'!$C$25:$G$31,MATCH($C39,'Допущения B'!$B$25:$B$31,0),4)) | I39: =IF($D39="","",$D39*INDEX('Допущения B'!$C$25:$G$31,MATCH($C39,'Допущения B'!$B$25:$B$31,0),5)) | J39: =SUM(E39:I39) -> 0 | L39: Своя статья
B40: Итого по блоку | E40: =SUM(E35:E39) -> 906000 | F40: =SUM(F35:F39) -> 1377600 | G40: =SUM(G35:G39) -> 1971916.8 | H40: =SUM(H35:H39) -> 2554159.1 | I40: =SUM(I35:I39) -> 3294949.5 | J40: =SUM(J35:J39) -> 10104625 | K40: =IFERROR(J40/$J$51,0) -> 0.22287648
B42: БЛОК 5. Разовые затраты и комплаенс
B43: Юридический и комплаенс-аудит (NDPR, POPIA, KICA) | C43: фикс | D43: 25000 | E43: 25000 | F43: 10000 | G43: 10000 | H43: 10000 | I43: 10000 | J43: =SUM(E43:I43) -> 65000 | L43: Аудит NDPR/POPIA/KDPA; далее ежегодный audit return NDPC (A3 п.1) (годы 2–5 перезаписаны вручную, как требует инструкция C25)
B44: Пентест и аудит безопасности | C44: инфляция | D44: 15000 | E44: =IF($D44="","",$D44*INDEX('Допущения B'!$C$25:$G$31,MATCH($C44,'Допущения B'!$B$25:$B$31,0),1)) -> 15000 | F44: =IF($D44="","",$D44*INDEX('Допущения B'!$C$25:$G$31,MATCH($C44,'Допущения B'!$B$25:$B$31,0),2)) -> 16200 | G44: =IF($D44="","",$D44*INDEX('Допущения B'!$C$25:$G$31,MATCH($C44,'Допущения B'!$B$25:$B$31,0),3)) -> 17496 | H44: =IF($D44="","",$D44*INDEX('Допущения B'!$C$25:$G$31,MATCH($C44,'Допущения B'!$B$25:$B$31,0),4)) -> 18895.68 | I44: =IF($D44="","",$D44*INDEX('Допущения B'!$C$25:$G$31,MATCH($C44,'Допущения B'!$B$25:$B$31,0),5)) -> 20407.334 | J44: =SUM(E44:I44) -> 87999.014 | L44: Пентест ежегодно
B45: Миграция данных и интеграции при запуске | C45: фикс | D45: 25000 | E45: =$D45 -> 25000 | F45: 0 | G45: 0 | H45: 0 | I45: 0 | J45: =SUM(E45:I45) -> 25000 | L45: Интеграции + контракты между сервисами - разовая, годы 2–5 обнулены вручную
B46: Обучение команды и найм | C46: ФОТ | D46: 25000 | E46: =IF($D46="","",$D46*INDEX('Допущения B'!$C$25:$G$31,MATCH($C46,'Допущения B'!$B$25:$B$31,0),1)) -> 25000 | F46: =IF($D46="","",$D46*INDEX('Допущения B'!$C$25:$G$31,MATCH($C46,'Допущения B'!$B$25:$B$31,0),2)) -> 28000 | G46: =IF($D46="","",$D46*INDEX('Допущения B'!$C$25:$G$31,MATCH($C46,'Допущения B'!$B$25:$B$31,0),3)) -> 31360 | H46: =IF($D46="","",$D46*INDEX('Допущения B'!$C$25:$G$31,MATCH($C46,'Допущения B'!$B$25:$B$31,0),4)) -> 35123.2 | I46: =IF($D46="","",$D46*INDEX('Допущения B'!$C$25:$G$31,MATCH($C46,'Допущения B'!$B$25:$B$31,0),5)) -> 39337.984 | J46: =SUM(E46:I46) -> 158821.18 | L46: Найм 2 разработчиков + SRE
...

Sheet Допущения C
B2: Допущения модели TCO - вариант C: Микросервисы CTO (40-50 сервисов)
B3: Заполняются только ячейки с жёлтой заливкой. Все числа ниже - пример, заменить своими.
B5: 1. Драйверы бизнеса - заполнить
B6: Показатель | C6: Год 1 | D6: Год 2 | E6: Год 3 | F6: Год 4 | G6: Год 5 | H6: Комментарий / источник
B7: Активные пользователи (на конец года) | C7: ='Допущения A'!C7 -> 400000 | D7: ='Допущения A'!D7 -> 1200000 | E7: ='Допущения A'!E7 -> 2500000 | F7: ='Допущения A'!F7 -> 4000000 | G7: ='Допущения A'!G7 -> 6000000 | H7: Ссылка на «Допущения A» - единые драйверы для всех вариантов
B8: Число заказов в год | C8: ='Допущения A'!C8 -> 600000 | D8: ='Допущения A'!D8 -> 2400000 | E8: ='Допущения A'!E8 -> 6000000 | F8: ='Допущения A'!F8 -> 11000000 | G8: ='Допущения A'!G8 -> 18000000 | H8: Ссылка на «Допущения A» - единые драйверы для всех вариантов
B9: Средний чек (AOV), $ | C9: ='Допущения A'!C9 -> 20 | D9: ='Допущения A'!D9 -> 21 | E9: ='Допущения A'!E9 -> 22 | F9: ='Допущения A'!F9 -> 23 | G9: ='Допущения A'!G9 -> 24 | H9: Ссылка на «Допущения A» - единые драйверы для всех вариантов
B10: GMV, $ в год (расчёт) | C10: =C8*C9 -> 12000000 | D10: =D8*D9 -> 50400000 | E10: =E8*E9 -> 132000000 | F10: =F8*F9 -> 253000000 | G10: =G8*G9 -> 432000000 | H10: Расчёт: заказы × средний чек
B12: 2. Финансовые допущения - заполнить
B13: Параметр | C13: Значение | H13: Комментарий / источник
B14: Инфляция затрат, % в год | C14: 0.08 | H14: Применяется к статьям с драйвером «инфляция»
B15: Рост ФОТ, % в год | C15: 0.12 | H15: Дефицит ИТ-специалистов на рынке - рост выше инфляции
B16: Ставка дисконтирования, % в год | C16: 0.2 | H16: Для расчёта NPV затрат. Стартап, высокий риск
B17: Резерв на непредвиденное (contingency), % | C17: 0.15 | H17: Надбавка к прямым затратам
B18: Бюджет CFO на облако, $/мес | C18: 5000 | H18: A6 п.1: $5 000/мес - жёсткий потолок, включая мониторинг и SaaS. $9 000 - цифра из board deck, разработке недоступна
B19: Стоимость минуты простоя, $ | C19: 12000 | H19: Оценка инвестора «в распродажу» (A1, A7). В блоке 6 минута считается от GMV, плоские $12k - на листе «Сравнение»
B20: Целевой SLO (доступность), % | C20: 0.9999 | H20: Active-active, RPO=0 (A5)
B21: Учитывать стоимость простоя в TCO (1 - да, 0 - нет) | C21: 1 | H21: Переключатель для сценарного анализа
B22: Коэффициент пиковости простоя (× к средней GMV/мин) | C22: 5 | H22: Сбои концентрируются в часы пик и распродаж
B23: 3. Индексы роста - расчёт, не редактировать
B24: Драйвер | C24: Год 1 | D24: Год 2 | E24: Год 3 | F24: Год 4 | G24: Год 5 | H24: Как считается
B25: фикс | C25: 1 | D25: 1 | E25: 1 | F25: 1 | G25: 1 | H25: Затраты не меняются по годам
